2023-04-26 13:30:42,879 INFO    StreamThr :11332 [internal.py:wandb_internal():86] W&B internal server running at pid: 11332, started at: 2023-04-26 13:30:42.878036
2023-04-26 13:30:42,881 DEBUG   HandlerThread:11332 [handler.py:handle_request():144] handle_request: status
2023-04-26 13:30:42,883 INFO    WriterThread:11332 [datastore.py:open_for_write():85] open: /home/tbarba/projects/MultiModalBrainSurvival/wandb/run-20230426_133042-VAE3D_UKB/run-VAE3D_UKB.wandb
2023-04-26 13:30:42,889 DEBUG   SenderThread:11332 [sender.py:send():375] send: header
2023-04-26 13:30:42,920 DEBUG   SenderThread:11332 [sender.py:send():375] send: run
2023-04-26 13:30:43,095 ERROR   SenderThread:11332 [internal_api.py:execute():288] 409 response executing GraphQL.
2023-04-26 13:30:43,095 ERROR   SenderThread:11332 [internal_api.py:execute():289] {"errors":[{"message":"run tbarba19/Brain_VAE/VAE3D_UKB was previously created and deleted; try a new run name","path":["upsertBucket"]}],"data":{"upsertBucket":null}}
2023-04-26 13:30:44,252 ERROR   SenderThread:11332 [internal_api.py:execute():288] 409 response executing GraphQL.
2023-04-26 13:30:44,252 ERROR   SenderThread:11332 [internal_api.py:execute():289] {"errors":[{"message":"run tbarba19/Brain_VAE/VAE3D_UKB was previously created and deleted; try a new run name","path":["upsertBucket"]}],"data":{"upsertBucket":null}}
2023-04-26 13:30:46,562 ERROR   SenderThread:11332 [internal_api.py:execute():288] 409 response executing GraphQL.
2023-04-26 13:30:46,562 ERROR   SenderThread:11332 [internal_api.py:execute():289] {"errors":[{"message":"run tbarba19/Brain_VAE/VAE3D_UKB was previously created and deleted; try a new run name","path":["upsertBucket"]}],"data":{"upsertBucket":null}}
2023-04-26 13:30:46,563 INFO    SenderThread:11332 [retry.py:__call__():172] Retry attempt failed:
Traceback (most recent call last):
  File "/labs/gevaertlab/users/thomas/miniconda/envs/multimodal/lib/python3.9/site-packages/wandb/sdk/lib/retry.py", line 131, in __call__
    result = self._call_fn(*args, **kwargs)
  File "/labs/gevaertlab/users/thomas/miniconda/envs/multimodal/lib/python3.9/site-packages/wandb/sdk/internal/internal_api.py", line 285, in execute
    return self.client.execute(*args, **kwargs)  # type: ignore
  File "/labs/gevaertlab/users/thomas/miniconda/envs/multimodal/lib/python3.9/site-packages/wandb/vendor/gql-0.2.0/wandb_gql/client.py", line 52, in execute
    result = self._get_result(document, *args, **kwargs)
  File "/labs/gevaertlab/users/thomas/miniconda/envs/multimodal/lib/python3.9/site-packages/wandb/vendor/gql-0.2.0/wandb_gql/client.py", line 60, in _get_result
    return self.transport.execute(document, *args, **kwargs)
  File "/labs/gevaertlab/users/thomas/miniconda/envs/multimodal/lib/python3.9/site-packages/wandb/sdk/lib/gql_request.py", line 56, in execute
    request.raise_for_status()
  File "/labs/gevaertlab/users/thomas/miniconda/envs/multimodal/lib/python3.9/site-packages/requests/models.py", line 1021, in raise_for_status
    raise HTTPError(http_error_msg, response=self)
requests.exceptions.HTTPError: 409 Client Error: Conflict for url: https://api.wandb.ai/graphql
2023-04-26 13:30:47,922 DEBUG   HandlerThread:11332 [handler.py:handle_request():144] handle_request: keepalive
2023-04-26 13:30:51,099 ERROR   SenderThread:11332 [internal_api.py:execute():288] 409 response executing GraphQL.
2023-04-26 13:30:51,099 ERROR   SenderThread:11332 [internal_api.py:execute():289] {"errors":[{"message":"run tbarba19/Brain_VAE/VAE3D_UKB was previously created and deleted; try a new run name","path":["upsertBucket"]}],"data":{"upsertBucket":null}}
2023-04-26 13:30:52,924 DEBUG   HandlerThread:11332 [handler.py:handle_request():144] handle_request: keepalive
2023-04-26 13:30:57,926 DEBUG   HandlerThread:11332 [handler.py:handle_request():144] handle_request: keepalive
2023-04-26 13:31:00,746 ERROR   SenderThread:11332 [internal_api.py:execute():288] 409 response executing GraphQL.
2023-04-26 13:31:00,747 ERROR   SenderThread:11332 [internal_api.py:execute():289] {"errors":[{"message":"run tbarba19/Brain_VAE/VAE3D_UKB was previously created and deleted; try a new run name","path":["upsertBucket"]}],"data":{"upsertBucket":null}}
2023-04-26 13:31:02,928 DEBUG   HandlerThread:11332 [handler.py:handle_request():144] handle_request: keepalive
2023-04-26 13:31:07,931 DEBUG   HandlerThread:11332 [handler.py:handle_request():144] handle_request: keepalive
2023-04-26 13:31:12,932 DEBUG   HandlerThread:11332 [handler.py:handle_request():144] handle_request: keepalive
2023-04-26 13:31:17,934 DEBUG   HandlerThread:11332 [handler.py:handle_request():144] handle_request: keepalive
2023-04-26 13:31:20,380 ERROR   SenderThread:11332 [internal_api.py:execute():288] 409 response executing GraphQL.
2023-04-26 13:31:20,380 ERROR   SenderThread:11332 [internal_api.py:execute():289] {"errors":[{"message":"run tbarba19/Brain_VAE/VAE3D_UKB was previously created and deleted; try a new run name","path":["upsertBucket"]}],"data":{"upsertBucket":null}}
2023-04-26 13:31:21,482 DEBUG   HandlerThread:11332 [handler.py:handle_request():144] handle_request: shutdown
2023-04-26 13:31:21,482 INFO    HandlerThread:11332 [handler.py:finish():845] shutting down handler
2023-04-26 13:31:21,927 INFO    WriterThread:11332 [datastore.py:close():298] close: /home/tbarba/projects/MultiModalBrainSurvival/wandb/run-20230426_133042-VAE3D_UKB/run-VAE3D_UKB.wandb
2023-04-26 13:31:55,785 ERROR   SenderThread:11332 [internal_api.py:execute():288] 409 response executing GraphQL.
2023-04-26 13:31:55,785 ERROR   SenderThread:11332 [internal_api.py:execute():289] {"errors":[{"message":"run tbarba19/Brain_VAE/VAE3D_UKB was previously created and deleted; try a new run name","path":["upsertBucket"]}],"data":{"upsertBucket":null}}
2023-04-26 13:33:03,309 ERROR   SenderThread:11332 [internal_api.py:execute():288] 409 response executing GraphQL.
2023-04-26 13:33:03,310 ERROR   SenderThread:11332 [internal_api.py:execute():289] {"errors":[{"message":"run tbarba19/Brain_VAE/VAE3D_UKB was previously created and deleted; try a new run name","path":["upsertBucket"]}],"data":{"upsertBucket":null}}
2023-04-26 13:33:03,310 ERROR   SenderThread:11332 [sender.py:send_run():979] run tbarba19/Brain_VAE/VAE3D_UKB was previously created and deleted; try a new run name (Error 409: Conflict)
Traceback (most recent call last):
  File "/labs/gevaertlab/users/thomas/miniconda/envs/multimodal/lib/python3.9/site-packages/wandb/apis/normalize.py", line 41, in wrapper
    return func(*args, **kwargs)
  File "/labs/gevaertlab/users/thomas/miniconda/envs/multimodal/lib/python3.9/site-packages/wandb/sdk/internal/internal_api.py", line 1690, in upsert_run
    response = self.gql(
  File "/labs/gevaertlab/users/thomas/miniconda/envs/multimodal/lib/python3.9/site-packages/wandb/sdk/internal/internal_api.py", line 257, in gql
    ret = self._retry_gql(
  File "/labs/gevaertlab/users/thomas/miniconda/envs/multimodal/lib/python3.9/site-packages/wandb/sdk/lib/retry.py", line 131, in __call__
    result = self._call_fn(*args, **kwargs)
  File "/labs/gevaertlab/users/thomas/miniconda/envs/multimodal/lib/python3.9/site-packages/wandb/sdk/internal/internal_api.py", line 285, in execute
    return self.client.execute(*args, **kwargs)  # type: ignore
  File "/labs/gevaertlab/users/thomas/miniconda/envs/multimodal/lib/python3.9/site-packages/wandb/vendor/gql-0.2.0/wandb_gql/client.py", line 52, in execute
    result = self._get_result(document, *args, **kwargs)
  File "/labs/gevaertlab/users/thomas/miniconda/envs/multimodal/lib/python3.9/site-packages/wandb/vendor/gql-0.2.0/wandb_gql/client.py", line 60, in _get_result
    return self.transport.execute(document, *args, **kwargs)
  File "/labs/gevaertlab/users/thomas/miniconda/envs/multimodal/lib/python3.9/site-packages/wandb/sdk/lib/gql_request.py", line 56, in execute
    request.raise_for_status()
  File "/labs/gevaertlab/users/thomas/miniconda/envs/multimodal/lib/python3.9/site-packages/requests/models.py", line 1021, in raise_for_status
    raise HTTPError(http_error_msg, response=self)
requests.exceptions.HTTPError: 409 Client Error: Conflict for url: https://api.wandb.ai/graphql

During handling of the above exception, another exception occurred:

Traceback (most recent call last):
  File "/labs/gevaertlab/users/thomas/miniconda/envs/multimodal/lib/python3.9/site-packages/wandb/sdk/internal/sender.py", line 977, in send_run
    self._init_run(run, config_value_dict)
  File "/labs/gevaertlab/users/thomas/miniconda/envs/multimodal/lib/python3.9/site-packages/wandb/sdk/internal/sender.py", line 1015, in _init_run
    server_run, inserted, server_messages = self._api.upsert_run(
  File "/labs/gevaertlab/users/thomas/miniconda/envs/multimodal/lib/python3.9/site-packages/wandb/apis/normalize.py", line 51, in wrapper
    raise CommError(message, error)
wandb.errors.CommError: run tbarba19/Brain_VAE/VAE3D_UKB was previously created and deleted; try a new run name (Error 409: Conflict)
2023-04-26 13:33:03,341 INFO    SenderThread:11332 [sender.py:finish():1550] shutting down sender
